Validation report for ogc.bbr.template.mod-dcat-bblock - MOD-DCAT-Profile
Generated 2023-12-13T13:11:10.023797+00:00
=== Files ===
Using example_1_1.json from examples
JSON-LD context is present - uplifting
Output JSON-LD example_1_1.jsonld created
Output Turtle example_1_1.ttl created
=== End Files ===

=== JSON Schema ===
Using the following JSON Schema: #/$defs/SemanticArtefact
=== End JSON Schema ===

=== Unknown errors ===

** Validation error **
Traceback (most recent call last):
,  File "/venv/lib/python3.10/site-packages/jsonschema/validators.py", line 966, in resolve_fragment
    document = document[part]
,KeyError: 'SemanticArtefact'
,
During handling of the above exception, another exception occurred:

,Traceback (most recent call last):
,  File "/src/ogc/bblocks/validate.py", line 483, in validate_inner
    validate_json(json_doc, schema_validator)
,  File "/src/ogc/bblocks/validate.py", line 842, in validate_json
    error = jsonschema.exceptions.best_match(validator.iter_errors(instance))
,  File "/venv/lib/python3.10/site-packages/jsonschema/exceptions.py", line 384, in best_match
    best = next(errors, None)
,  File "/venv/lib/python3.10/site-packages/jsonschema/validators.py", line 288, in iter_errors
    for error in errors:
,  File "/venv/lib/python3.10/site-packages/jsonschema/_validators.py", line 294, in ref
    scope, resolved = validator.resolver.resolve(ref)
,  File "/venv/lib/python3.10/site-packages/jsonschema/validators.py", line 898, in resolve
    return url, self._remote_cache(url)
,  File "/venv/lib/python3.10/site-packages/jsonschema/validators.py", line 916, in resolve_from_url
    return self.resolve_fragment(document, fragment)
,  File "/venv/lib/python3.10/site-packages/jsonschema/validators.py", line 968, in resolve_fragment
    raise exceptions.RefResolutionError(
,jsonschema.exceptions.RefResolutionError: Unresolvable JSON pointer: '$defs/SemanticArtefact'
,
During handling of the above exception, another exception occurred:

,Traceback (most recent call last):
,  File "/src/ogc/bblocks/validate.py", line 606, in _validate_resource
    validate_inner()
,  File "/src/ogc/bblocks/validate.py", line 503, in validate_inner
    'errorMessage': e.message,
,AttributeError: 'RefResolutionError' object has no attribute 'message'

=== End Unknown errors ===

